<?xml version="1.0"?>
<robot name="Dishwasher_12580_0_1_model">
  <link name="base"/>

  <link name="base_link">
    <visual>
      <geometry><mesh filename="./mesh_parts/body_rest.obj" scale="1 1 1"/></geometry>
    </visual>
    <collision>
      <geometry><mesh filename="./mesh_parts/body_rest.obj" scale="1 1 1"/></geometry>
    </collision>
  </link>

  <joint name="fixed_base_to_baselink" type="fixed">
    <parent link="base"/>
    <child link="base_link"/>
    <origin xyz="0 0 0" rpy="0 0 0"/>
  </joint>

  <link name="prop0_inst0_link">
    <visual>
      <origin xyz="0.478664994 -1.780395031 0.570465267" rpy="0 0 0"/>
      <geometry><mesh filename="./mesh_parts/prop0_inst0_part.obj" scale="1 1 1"/></geometry>
    </visual>
    <!-- <collision>
      <origin xyz="0.478664994 -1.780395031 0.570465267" rpy="0 0 0"/>
      <geometry><mesh filename="./mesh_parts/prop0_inst0_part.obj" scale="1 1 1"/></geometry>
    </collision> -->
  </link>

  <joint name="prop0_inst0_hinge" type="revolute">
    <parent link="base_link"/>
    <child link="prop0_inst0_link"/>
    <origin xyz="-0.478664994 1.780395031 -0.570465267" rpy="0 0 0"/>
    <axis xyz="-0.004364385 0.999989927 -0.001054288"/>
    <limit lower="0.0" upper="100.0"/>
  </joint>

</robot>